Workbook

Sheet Exhibit 1
A1: Exhibit 1 Financial Statements for 1975
A3: Balance Sheet
A4: As of December 31,1975
A5: Assets | D5: Liabilities and Fund Balances
A6: Cash | B6: 30934 | D6: Accounts Payable | E6: 32754
A7: Accounts Receivable | B7: 8800 | D7: Accrued wages | E7: 3466
A8: Inventory | B8: 40540 | D8: Total Current | F8: 36220
A9: Total Current | C9: 80274
D10: Bank Loan | F10: 27550
A11: Furniture & Equipment | B11: 21700 | D11: Total Liabilities | F11: 63770
A12: Less: Accumulated
A13: Depreciation | B13: 8788 | D13: Fund Balances:
A14: Total fixed | C14: 12912 | D14: Designated by board for
D15: Special Outreach Project | E15: 25000
A16: Total Assets | C16: 93186 | D16: Purchases of new equip. | E16: 3000
D17: Undesignated | E17: 1416
D18: Total Fund balances | F18: 29416
D19: Total Liabilities and Fund
D20: Balances | F20: 93186
A22: Income Statement
A23: 1975
A24: Revenue from patient fees | C24: 345450
A25: Other revenue | C25: 5000
A26: Total Revenue | C26: 350450
A28: Expenses
A29: Program services | B29: 235000
A30: Utilities | B30: 10000
A31: Laboratory | B31: 25000
A32: General and Administrative | B32: 92000
A33: Total Expenses | C33: 362000
A35: Surplus (Deficit) | C35: -11550

Sheet Exhibit 2
A1: Exhibit 2 Costs and Patient Visits1 for 1975, By Department
C3: Expenses
A4: Department | B4: Number Patient Visits | C4: Salaries2 | D4: Others3 | E4: Total
A5: Pediatrics | B5: 5000 | C5: 20000 | D5: 8000 | E5: 28000
A6: Family Planning | B6: 10000 | C6: 5000 | D6: 15000 | E6: 20000
A7: Adult Medicine | B7: 2100 | C7: 30000 | D7: 16000 | E7: 46000
A8: Nursing | B8: 4000 | C8: 27000 | D8: 6000 | E8: 33000
A9: Mental Health | B9: 1400 | C9: 15000 | D9: 8000 | E9: 23000
A10: Social Services | B10: 1500 | C10: 32000 | D10: 8000 | E10: 40000
A11: Community Health | B11: 2500 | C11: 5000 | D11: 10000 | E11: 15000
A12: Dental | B12: 6400 | C12: 20000 | D12: 10000 | E12: 30000
A13: Sub-Total | B13: =SUM(B5:B12) -> 32900 | C13: =SUM(C5:C12) -> 154000 | D13: =SUM(D5:D12) -> 81000 | E13: =SUM(E5:E12) -> 235000
A14: Administration | C14: 38000 | D14: 2000 | E14: 40000
A15: Rent | D15: 36000 | E15: 36000 | G15: Rent, Util, Cleaning | I15: =SUM(E15,E16,E18) -> 52000
A16: Utilities | D16: 10000 | E16: 10000 | G16: Admin | I16: =SUM(E14) -> 40000
A17: Laboratory Work | C17: 16000 | D17: 9000 | E17: 25000
A18: Cleaning | D18: 6000 | E18: 6000
A19: Record Keeping | C19: 7000 | D19: 3000 | E19: 10000
A20: Total | C20: =SUM(C13:C19) -> 215000 | D20: 147000 | E20: 362000
A21: Number of Patient Visits | E21: 32900
A22: Average Cost per Visit | E22: 11
A24: 1Patient visits rounded to nearest 100; Expenses rounded to nearest 1,000
A25: 2Includes fringe benefits
A26: 3Materials, supplies, contracted services, depreciation and other non-personnel expenses

Sheet Exhibit 3
A1: Exhibit 3 Floor Space and Laboratory Usage1 by Department
A3: Department | B3: Floor Space2 | C3: Laboratory Usage3
A4: Pediatrics | B4: 1000 | C4: 1000 | D4: =C4/$C$15 -> 0.25
A5: Family Planning | B5: 1300 | C5: 200 | D5: =C5/$C$15 -> 0.05
A6: Adult Medicine | B6: 1800 | C6: 2400 | D6: =C6/$C$15 -> 0.6
A7: Nursing | B7: 300 | C7: 100 | D7: =C7/$C$15 -> 0.025
A8: Mental Health | B8: 1000 | C8: ---
A9: Social Services | B9: 500 | C9: ---
A10: Community Health | B10: 1100 | C10: 100 | D10: =C10/$C$15 -> 0.025
A11: Dental | B11: 1000 | C11: 200 | D11: =C11/$C$15 -> 0.05
A12: Administration | B12: 500 | C12: ---
A13: Record Keeping | B13: 300 | C13: ---
A14: Laboratory Work | B14: 1200 | C14: ---
A15: Total | B15: 10000 | C15: 4000
A17: 1Rounded to nearest 100
A18: 2 In Square Feet
A19: 3In hours/year

Sheet Allocation
B1: Current | C1: Direct Cost | D1: Rent, Utilities & Cleaning | E1: Administration | F1: Record Keeping | G1: Social Services (BA) | H1: Social Services (MSW) | I1: Nursing | J1: TOTAL | K1: Drivers | L1: Charges per visit (or hour) | N1: Direct Cost + Service Dept | O1: Nursing | P1: TOTAL | Q1: Charges per visit (or hour) | R1: Social Services (MSW) | S1: Social Services (BA)
A2: Production | B2: Pediatrics | C2: ='Exhibit 2'!E5*IF($B$1="Projected",1.1,1) -> 28000 | D2: =Y3*52000 -> 5200 | E2: =T24*$T$41 -> 4813.5593 | F2: =U24*$Y$39 -> 2012.8793 | G2: =$AC$32 -> 1818.0557 | H2: =$Z$34 -> 3181.5974 | I2: =$Z$48 -> 7111.4348 | J2: =SUM(C2:I2) -> 52137.526 | K2: ='Exhibit 2'!B5*IF($B$1="Projected",1.1,1) -> 5000 | L2: =J2/K2 -> 10.427505 | N2: =SUM(C2:F2) -> 40026.439 | O2: =Z48 -> 7111.4348 | P2: =SUM(N2:O2) -> 47137.873 | Q2: =P2/K2 -> 9.4275747 | V2: Department | W2: Floor Space2 | X2: Laboratory Usage3 | Y2: % usage
B3: Family Planning | C3: ='Exhibit 2'!E6*IF($B$1="Projected",1.1,1) -> 20000 | D3: =Y4*52000 -> 6760 | E3: =T25*$T$41 -> 1203.3898 | F3: =U25*$Y$39 -> 4025.7586 | G3: =$AC$32 -> 1818.0557 | H3: =$Z$34 -> 3181.5974 | I3: =$Z$48 -> 7111.4348 | J3: =SUM(C3:I3) -> 44100.236 | K3: ='Exhibit 2'!B6*IF($B$1="Projected",1.1,1) -> 10000 | L3: =J3/K3 -> 4.4100236 | N3: =SUM(C3:F3) -> 31989.148 | O3: =Z48 -> 7111.4348 | P3: =SUM(N3:O3) -> 39100.583 | Q3: =P3/K3 -> 3.9100583 | V3: Pediatrics | W3: 1000 | X3: 1000 | Y3: =W3/$W$14 -> 0.1
B4: Adult Medicine | C4: ='Exhibit 2'!E7*IF($B$1="Projected",1.1,1) -> 46000 | D4: =Y5*52000 -> 9360 | E4: =T26*$T$41 -> 7220.339 | F4: =U26*$Y$39 -> 845.4093 | G4: =$AC$32 -> 1818.0557 | H4: =$Z$34 -> 3181.5974 | I4: =Y50 -> 14222.87 | J4: =SUM(C4:I4) -> 82648.271 | K4: ='Exhibit 2'!B7*IF($B$1="Projected",1.1,1) -> 2100 | L4: =J4/K4 -> 39.356319 | N4: =SUM(C4:F4) -> 63425.748 | O4: =Y48 -> 14222.87 | P4: =SUM(N4:O4) -> 77648.618 | Q4: =P4/K4 -> 36.975532 | V4: Family Planning | W4: 1300 | X4: 200 | Y4: =W4/$W$14 -> 0.13
B5: Nursing | C5: ='Exhibit 2'!E8*IF($B$1="Projected",1.1,1) -> 33000 | D5: =Y6*52000 -> 1560 | E5: =T27*$T$41 -> 6498.3051 | F5: =U27*$Y$39 -> 1610.3034 | G5: =$AC$32 -> 1818.0557 | H5: =$Z$34 -> 3181.5974 | I5: =-(Y47-Y49) -> -28445.739 | J5: =SUM(C5:I5) -> 19222.523 | K5: ='Exhibit 2'!B8*IF($B$1="Projected",1.1,1) -> 4000 | L5: =J5/K5 -> 4.8056306 | N5: =SUM(C5:F5) -> 42668.609 | O5: =-(Y47-Y49) -> -28445.739 | P5: =SUM(N5:O5) -> 14222.87 | Q5: =P5/K5 -> 3.5557174 | V5: Adult Medicine | W5: 1800 | X5: 2400 | Y5: =W5/$W$14 -> 0.18
B6: Mental Health | C6: ='Exhibit 2'!E9*IF($B$1="Projected",1.1,1) -> 23000 | D6: =Y7*52000 -> 5200 | E6: =T28*$T$41 -> 3610.1695 | F6: =U28*$Y$39 -> 563.6062 | G6: =$AC$32 -> 1818.0557 | H6: =$Z$34 -> 3181.5974 | J6: =SUM(C6:I6) -> 37373.429 | K6: ='Exhibit 2'!B9*IF($B$1="Projected",1.1,1) -> 1400 | L6: =J6/K6 -> 26.695306 | N6: =SUM(C6:F6) -> 32373.776 | P6: =SUM(N6:O6) -> 32373.776 | Q6: =P6/K6 -> 23.124125 | V6: Nursing | W6: 300 | X6: 100 | Y6: =W6/$W$14 -> 0.03
B7: Social Services | C7: ='Exhibit 2'!E10*IF($B$1="Projected",1.1,1) -> 40000 | D7: =Y8*52000 -> 2600 | E7: =T29*$T$41 -> 7701.6949 | F7: =U29*$Y$39 -> 603.86379 | G7: =-Y29+AC32 -> -10908.334 | H7: =-Z32 -> -19089.585 | J7: =SUM(C7:I7) -> 20907.64 | K7: ='Exhibit 2'!B10*IF($B$1="Projected",1.1,1) -> 1500 | L7: =J7/K7 -> 13.938427 | N7: =SUM(C7:F7) -> 50905.559 | P7: =SUM(N7:O7) -> 50905.559 | R7: =(X28*X27)/4000 -> 9.5447923 | S7: =(X28*Y27)/2000 -> 6.3631948 | V7: Mental Health | W7: 1000 | X7: --- | Y7: =W7/$W$14 -> 0.1
B8: Community Health | C8: ='Exhibit 2'!E11*IF($B$1="Projected",1.1,1) -> 15000 | D8: =Y9*52000 -> 5720 | E8: =T30*$T$41 -> 1203.3898 | F8: =U30*$Y$39 -> 1006.4396 | G8: =$AC$32 -> 1818.0557 | H8: =$Z$34 -> 3181.5974 | J8: =SUM(C8:I8) -> 27929.483 | K8: ='Exhibit 2'!B11*IF($B$1="Projected",1.1,1) -> 2500 | L8: =J8/K8 -> 11.171793 | N8: =SUM(C8:F8) -> 22929.829 | P8: =SUM(N8:O8) -> 22929.829 | Q8: =P8/K8 -> 9.1719318 | V8: Social Services | W8: 500 | X8: --- | Y8: =W8/$W$14 -> 0.05
B9: Dental | C9: ='Exhibit 2'!E12*IF($B$1="Projected",1.1,1) -> 30000 | D9: =Y10*52000 -> 5200 | E9: =T31*$T$41 -> 4813.5593 | F9: =U31*$Y$39 -> 2576.4855 | J9: =SUM(C9:I9) -> 42590.045 | K9: ='Exhibit 2'!B12*IF($B$1="Projected",1.1,1) -> 6400 | L9: =J9/K9 -> 6.6546945 | N9: =SUM(C9:F9) -> 42590.045 | P9: =SUM(N9:O9) -> 42590.045 | Q9: =P9/K9 -> 6.6546945 | V9: Community Health | W9: 1100 | X9: 100 | Y9: =W9/$W$14 -> 0.11
A10: Service | B10: Administration | C10: ='Exhibit 2'!E14*IF($B$1="Projected",1.1,1) -> 40000 | D10: =Y11*52000 -> 2600 | E10: =-SUM(C10:D10) -> -42600 | J10: =SUM(C10:I10) -> 0 | N10: =SUM(C10:F10) -> 0 | P10: =SUM(N10:O10) -> 0 | V10: Dental | W10: 1000 | X10: 200 | Y10: =W10/$W$14 -> 0.1
B11: Rent, Utilities & Cleaning | C11: =SUM('Exhibit 2'!E15:E16,'Exhibit 2'!E18)*IF($B$1="Projected",1.1,1) -> 52000 | D11: =-C11 -> -52000 | E11: =-SUM(C11:D11) -> 0 | J11: =SUM(C11:I11) -> 0 | N11: =SUM(C11:F11) -> 0 | P11: =SUM(N11:O11) -> 0 | V11: Administration | W11: 500 | X11: --- | Y11: =W11/$W$14 -> 0.05
B12: Laboratory Work | C12: ='Exhibit 2'!E17*IF($B$1="Projected",1.1,1) -> 25000 | D12: =Y13*52000 -> 6240 | E12: =T36*$T$41 -> 3850.8475 | J12: =SUM(C12:I12) -> 35090.847 | K12: ='Exhibit 3'!C15*IF($B$1="Projected",1.1,1) -> 4000 | L12: =J12/K12 -> 8.7727119 | N12: =SUM(C12:F12) -> 35090.847 | P12: =SUM(N12:O12) -> 35090.847 | Q12: =P12/K12 -> 8.7727119 | V12: Record Keeping | W12: 300 | X12: --- | Y12: =W12/$W$14 -> 0.03
B13: Record Keeping | C13: ='Exhibit 2'!E19*IF($B$1="Projected",1.1,1) -> 10000 | D13: =Y12*52000 -> 1560 | E13: =T38*T41 -> 1684.7458 | F13: =-SUM(C13:E13) -> -13244.746 | J13: =SUM(C13:I13) -> 0 | N13: =SUM(C13:F13) -> 0 | P13: =SUM(N13:O13) -> 0 | V13: Laboratory Work | W13: 1200 | X13: --- | Y13: =W13/$W$14 -> 0.12
C14: =SUM(C2:C13) -> 362000 | D14: =SUM(D2:D13) -> 0 | E14: =SUM(E2:E13) -> -6.1390892e-12 | F14: =SUM(F2:F13) -> 0 | G14: =SUM(G2:G13) -> 0 | H14: =SUM(H2:H13) -> 0 | I14: =SUM(I2:I13) -> 0 | J14: =SUM(J2:J13) -> 362000 | N14: =SUM(N2:N13) -> 362000 | O14: =SUM(O2:O13) -> 0 | P14: =SUM(P2:P13) -> 362000 | R14: 0.95 | S14: 1 | V14: Total | W14: 10000 | X14: 4000
C16: Cost Driver | V16: 1Rounded to nearest 100
B17: Rent, Utilities & Cleaning | C17: Floor Space | V17: 2 In Square Feet
B18: Administration | C18: Salary | V18: 3In hours/year
B19: Record Keeping | C19: No of Patients visited
B20: Social Services - BA | C20: Equally to all incl SS, except Dental | O20: Exhibit 2 Costs and Patient Visits1 for 1975, By Department
B21: Social Services - MSW | C21: Equally to all excl SS, except Dental
B22: Nursing | C22: Specific (1:1:2) of 2/3rd expense | Q22: Expenses
O23: Department | P23: Number Patient Visits | Q23: Salaries2 | R23: Others3 | S23: Total | T23: % of salary | U23: % of patient | X23: Masters | Y23: Bachelors
I24: we need type of lab test | O24: Pediatrics | P24: 5000 | Q24: 20000 | R24: 8000 | S24: 28000 | T24: =Q24/$T$42 -> 0.11299435 | U24: =P24/$P$32 -> 0.15197568 | W24: number of worker | X24: 2 | Y24: 1
I25: and no. of hrs per lab test | O25: Family Planning | P25: 10000 | Q25: 5000 | R25: 15000 | S25: 20000 | T25: =Q25/$T$42 -> 0.028248588 | U25: =P25/$P$32 -> 0.30395137 | W25: salary | X25: 12000 | Y25: 8000
O26: Adult Medicine | P26: 2100 | Q26: 30000 | R26: 16000 | S26: 46000 | T26: =Q26/$T$42 -> 0.16949153 | U26: =P26/$P$32 -> 0.063829787 | X26: =X25*X24 -> 24000 | Y26: =Y25*Y24 -> 8000 | Z26: =Y26+X26 -> 32000
E27: Cost object is at a lower level -> measures cost seperately | O27: Nursing | P27: 4000 | Q27: 27000 | R27: 6000 | S27: 33000 | T27: =Q27/$T$42 -> 0.15254237 | U27: =P27/$P$32 -> 0.12158055 | X27: =X26/Z26 -> 0.75 | Y27: =Y26/Z26 -> 0.25
E28: Cost center -> incurred cost but not directly generate revenue | O28: Mental Health | P28: 1400 | Q28: 15000 | R28: 8000 | S28: 23000 | T28: =Q28/$T$42 -> 0.084745763 | U28: =P28/$P$32 -> 0.042553191 | W28: Total of CTC of social services | X28: =SUM(C7:F7) -> 50905.559
E29: Revenue center -> incurred cost generating direct revenue | O29: Social Services | P29: 1500 | Q29: 32000 | R29: 8000 | S29: 40000 | T29: =Q29/$T$42 -> 0.18079096 | U29: =P29/$P$32 -> 0.045592705 | X29: =X28*(X26/Z26) -> 38179.169 | Y29: =X28-X29 -> 12726.39
E30: Profit center -> standalone center which is expected to generate profit | O30: Community Health | P30: 2500 | Q30: 5000 | R30: 10000 | S30: 15000 | T30: =Q30/$T$42 -> 0.028248588 | U30: =P30/$P$32 -> 0.075987842
E31: Investment center -> | O31: Dental | P31: 6400 | Q31: 20000 | R31: 10000 | S31: 30000 | T31: =Q31/$T$42 -> 0.11299435 | U31: =P31/$P$32 -> 0.19452888
O32: Sub-Total | P32: =SUM(P24:P31) -> 32900 | Q32: =SUM(Q24:Q31) -> 154000 | R32: =SUM(R24:R31) -> 81000 | S32: =SUM(S24:S31) -> 235000 | X32: MSW spends 50% time in own dep | Z32: =X28*X27*(1/2) -> 19089.585 | AA32: BSW spends time serving all dep except dental | AC32: =Y29/7 -> 1818.0557
O33: Administration | Q33: 38000 | R33: 2000 | S33: 40000 | X33: and 50% time serving other dep | Z33: =Z32 -> 19089.585
E34: Revenue center linking to another center | O34: Rent | R34: 36000 | S34: 36000 | X34: cost per dep | Z34: =Z33/6 -> 3181.5974
O35: Utilities | R35: 10000 | S35: 10000
E36: unilateral interdependency | O36: Laboratory Work | Q36: 16000 | R36: 9000 | S36: 25000 | T36: =Q36/$T$42 -> 0.09039548
O37: Cleaning | R37: 6000 | S37: 6000
O38: Record Keeping | Q38: 7000 | R38: 3000 | S38: 10000 | T38: =Q38/$T$42 -> 0.039548023 | V38: total cost to company for Record keeping
O39: Total | Q39: =SUM(Q32:Q38) -> 215000 | R39: 147000 | S39: 362000 | V39: =S38 -> 10000 | W39: =E13 -> 1684.7458 | X39: =D13 -> 1560 | Y39: =SUM(V39:X39) -> 13244.746
O40: Number of Patient Visits | S40: 32900
O41: Average Cost per Visit | S41: 11 | T41: =S33+D10 -> 42600 | U41: <- total admin cost to be absorbed
...

Sheet Reciprocal Method
A2: Production | B2: Pediatrics | C2: 25000 | E2: Equation
B3: Dental | C3: 20000 | E3: Xray = 5000 + 0.2*Lab
A4: Service | B4: Xray | C4: 5000 | E4: Lab = 4400 + 0.1*Xray
B5: Lab | C5: 4400
E6: Xray = 5000 + .2*(4400 + .1*Xray)
B7: =B4 -> Xray | C7: =B5 -> Lab
A8: =B2 -> Pediatrics | B8: 0.5 | C8: 0.4 | E8: Solving for Xray,
A9: =B3 -> Dental | B9: 0.4 | C9: 0.4 | E9: =B4 -> Xray | F9: =(C4+C10*C5)/(1-C10*B11) -> 6000
A10: =B4 -> Xray | C10: 0.2 | E10: =B5 -> Lab | F10: =C5+0.1*F9 -> 5000
A11: =B5 -> Lab | B11: 0.1
B12: =SUM(B8:B11) -> 1 | C12: =SUM(C8:C11) -> 1
B16: Department | D16: {=TRANSPOSE(B2:B5)} -> Pediatrics | E16: Dental | F16: Xray | G16: Lab | H16: TOTAL
B17: Original Cost | D17: {=TRANSPOSE(C2:C5)} -> 25000 | E17: 20000 | F17: 5000 | G17: 4400 | H17: =SUM(D17:G17) -> 54400
B18: Distribution
B19: Xray | D19: =$F$9*B8 -> 3000 | E19: =$F$9*B9 -> 2400 | F19: =-F9 -> -6000 | G19: =$F$9*B11 -> 600 | H19: =$F$9*C11 -> 0
B20: Lab | D20: =$F$10*C8 -> 2000 | E20: =$F$10*C9 -> 2000 | F20: =$F$10*C10 -> 1000 | G20: =-F10 -> -5000 | H20: =-G10 -> 0
D21: =SUM(D17:D20) -> 30000 | E21: =SUM(E17:E20) -> 24400 | F21: =SUM(F17:F20) -> 0 | G21: =SUM(G17:G20) -> 0 | H21: =SUM(H17:H20) -> 54400
B23: Original Cost | D23: 25000 | E23: 20000 | F23: 5000 | G23: 4400
B24: Distribution | C24: Xray | D24: =-F24*0.5 -> 2500 | E24: =-F24*0.4 -> 2000 | F24: =-F23 -> -5000 | G24: =-F24*0.1 -> 500
D25: =SUM(D23:D24) -> 27500 | E25: =SUM(E23:E24) -> 22000 | F25: =SUM(F23:F24) -> 0 | G25: =SUM(G23:G24) -> 4900
C26: Lab | D26: =-G26*0.4 -> 1960 | E26: =-G26*0.4 -> 1960 | F26: =-G26*0.2 -> 980 | G26: =-G25 -> -4900
D27: =SUM(D25:D26) -> 29460 | E27: =SUM(E25:E26) -> 23960 | F27: =SUM(F25:F26) -> 980 | G27: =SUM(G25:G26) -> 0
C28: Xray | D28: =-F28*0.5 -> 490 | E28: =-F28*0.4 -> 392 | F28: =-F27 -> -980 | G28: =-F28*0.1 -> 98
D29: =SUM(D27:D28) -> 29950 | E29: =SUM(E27:E28) -> 24352 | F29: =SUM(F27:F28) -> 0 | G29: =SUM(G27:G28) -> 98
C30: Lab | D30: =-G30*0.4 -> 39.2 | E30: =-G30*0.4 -> 39.2 | F30: =-G30*0.2 -> 19.6 | G30: =-G29 -> -98
D31: =SUM(D29:D30) -> 29989.2 | E31: =SUM(E29:E30) -> 24391.2 | F31: =SUM(F29:F30) -> 19.6 | G31: =SUM(G29:G30) -> 0
C32: Xray | D32: =-F32*0.5 -> 9.8 | E32: =-F32*0.4 -> 7.84 | F32: =-F31 -> -19.6 | G32: =-F32*0.1 -> 1.96
D33: =SUM(D31:D32) -> 29999 | E33: =SUM(E31:E32) -> 24399.04 | F33: =SUM(F31:F32) -> 0 | G33: =SUM(G31:G32) -> 1.96
C34: Lab | D34: =-G34*0.4 -> 0.784 | E34: =-G34*0.4 -> 0.784 | F34: =-G34*0.2 -> 0.392 | G34: =-G33 -> -1.96
D35: =SUM(D33:D34) -> 29999.784 | E35: =SUM(E33:E34) -> 24399.824 | F35: =SUM(F33:F34) -> 0.392 | G35: =SUM(G33:G34) -> 0
